Workbook

Sheet Design_PROJECT
A1: 번호 | B1: 프로젝트코드 | C1: 프로젝트명 | D1: 이력코드 | E1: 발주처 | F1: 건설사 | G1: 소속팀 | H1: 담당자 | I1: 설계 | J1: 규모 | K1: 설계진행상황 | L1: 현재단계 | M1: 점수 | N1: 기타사항
A2: 1 | B2: D1946 | C2: 울산 율동지구 A-2블럭 환경디자인 | D2: [D1946] 심의1911~2011/기본2103~2201/대기 | E2: 에이비라인건축/대흥건축 | F2: 울산도시공사 | G2: GM | H2: 박상원 | L2: 대기 | N2: GM
A3: 2 | B3: D2048 | C3: 광주계림3 익스테리어 디자인 | D3: [D2048] 심의2103~11, 2301~10 / 대기 / 준공미정 | E3: 한화건설 | F3: 한화건설 | G3: TEAM | H3: 양수정 | J3: 10개동,1376세대 | L3: 대기 | N3: T1
A4: 3 | B4: D2105 | C4: 전주하가지구주택재개발정비사업특화설계 경관계획용역 | D4: [D2105] 재심의2412~ / 분양2610~ | E4: 현대종합설계 | F4: 현대건설 | G4: TEAM | H4: 양수정 | J4: 27개동,1994세대 | K4: 대기중 | L4: 기획 | M4: 5 | N4: T2,GM
A5: 4 | B5: D2147 | C5: 대전시 서구 탄방동 518-2번지 일원 공동주택 건축외관디자인 | D5: [D2147] 대기 / 준공미정 | E5: 유승디앤씨 | F5: 롯데건설 | G5: GM | H5: 박상원 | L5: 대기 | N5: GM
A6: 5 | B6: D2148 | C6: 거제시 옥포동 1670번지 일원 공동주택 건축외관디자인 | D6: [D2148] 심의2308~11 / 분양2608~09 / 설계2701~ | E6: 옥포드림파크 피에프브이 | F6: 현대엔지니어링 | G6: P3 | H6: 김주경 | J6: 14개동 | L6: 기본 | M6: 4
A7: 6 | B7: D2149 | C7: 가야동 197번지 공동주택 건축외관디자인 | D7: [D2150] 대기 / 기본2411~ / 준공2612 | E7: 세종앤파트너스7 | F7: 현대건설 | G7: GM | H7: 박상원 | J7: 3개동, 407세대 | K7: 1차 작업중 | L7: 현장지원 | M7: 2 | N7: GM
A8: 7 | B8: D2150 | C8: 가야동 197-3번지 공동주택 건축외관디자인 | D8: [D2150] 대기 / 기본2411~ / 준공2612 | E8: 가야도시개발 | F8: 현대건설 | G8: GM | H8: 박상원 | J8: 1개동, 81세대 | K8: 1차 작업중 | L8: 현장지원 | M8: 2 | N8: GM
A9: 8 | B9: D2202 | C9: 오송 KTX역 오피스텔 건축외관디자인 | D9: [D2202] 심의2203~07/분양2208~11/재심의2412~/분양2608~09/대기 | E9: 하나온개발 | F9: 현대엔지니어링 | G9: P3 | H9: 김주경 | J9: 2개블럭 17개동 | L9: 기본 | M9: 4
A10: 9 | B10: D2203 | C10: 대구신천동(137-1번지외) 주상복합 건축외관디자인 | D10: [D2203] 분양2210~2301 / 기본2307~2310, 2401~ / 설계2308~2310, 2401 / 준공2604 | E10: 모아에이엔씨 | F10: 현대건설 | G10: P3 | H10: 김주경 | I10: 홍대성 | J10: 4개동 | K10: 1차납품 완료(24.02.16) | L10: 현장지원 | M10: 2 | N10: T2
A11: 10 | B11: D2205 | C11: 의정부 호원 공공지원 민간임대주택 건축외관디자인 | D11: [D2205] 심의2208~09, 2312~2401 / 기본2407~2411 / 설계2407~2409, 2412 / 실시도서2506~10 / 준공2612 | E11: 호원임대주택조합 | F11: 현대건설 | G11: P1 | H11: 박제정 | J11: 12개동 | K11: 최종납품 완료(24.12.03) | L11: 현장지원 | M11: 2
A12: 11 | B12: D2206 | C12: 평택시 비전동 844번지외 5필지 주상복합 건축외관디자인 | D12: [D2206] 심의2204 , 2401~2410 / 대기 | E12: 이화글로베스트 | F12: - | G12: GM | H12: 박상원 | J12: 3개동,446세대 | L12: 대기 | N12: GM
A13: 12 | B13: D2208 | C13: 인천 청천대진 익스테리어 디자인용역 | D13: [D2208] 심의2203~07, 2210~2305, 2309~2312, 2402~ / 대기 / 준공미정 | E13: 한화건설 | F13: 한화건설 | G13: P1 | H13: 박제정 | J13: 6개동 | L13: 대기
A14: 13 | B14: D2209 | C14: 부산 청학1구역 익스테리어디자인 | D14: [D2209] 심의2206~2307 / 대기 / 준공미정 | E14: 한화건설 | F14: 한화건설 | G14: P1 | H14: 박제정 | J14: 3개동 | L14: 대기
A15: 14 | B15: D2215 | C15: 천안 성정동 주상복합 건축외관디자인 | D15: [D2215] 심의2206~09 /분양2209~10 / 기본2306~08, 2312~04 / 설계 2401~04 / 실시2601~07 / 준공2708 | E15: 천안성정동개발사업 | F15: 현대건설 | G15: P1 | H15: 박제정 | J15: 6개동/상환경 | K15: 1차송부 완료(24.03.29) | L15: 현장지원 | M15: 3
A16: 15 | B16: D2218 | C16: 양주회천지구 E2-1,2,3BL 주상복합 | D16: [D2218] 심의2205~12 / 대기 / 준공2505 | E16: 썸매니지먼트 | F16: 신화종합건설 | G16: P1 | H16: 박제정 | J16: 2개동 | L16: 대기
A17: 16 | B17: D2223 | C17: 대구 대봉1-2 주택재건축정비사업 외관디자인 | D17: [D2223] 심의2209~10 , 2608~ / 준공미정 | E17: 현대엔지니어링 | F17: 현대엔지니어링 | G17: P2 | H17: 최은진 | J17: 5개동 | L17: 기획 | M17: 5
A18: 17 | B18: D2226 | C18: 의정부 나리벡시티 도시개발사업 외부환경디자인(추가) | D18: [D2106] 심의2208~09,2312~2401 / 분양2208~11 / 기본2405~11 / 설계2406~11 / 실시2412 / 리비전 2610~ / 준공2612 | E18: 나리벡씨티개발 | F18: 롯데건설 | G18: P1 | H18: 박제정 | J18: 4개동 | K18: 최종납품 완료(24.11.29) | L18: 리비전 | M18: 2 | N18: 리비전단계
A19: 18 | B19: D2229 | C19: 하남교산 B-3BL 공동주택 설계용역(토탈디자인) | D19: [D2229] 심의2209~12, 2301~10 / 대기 / 준공3005 | E19: 한국토지주택공사LH | F19: 신동아건설 | G19: P3 | H19: 김주경 | J19: 13개동 | L19: 대기
A20: 19 | B20: D2236 | C20: 잠실 스포츠MICE 색채사인디자인 | D20: [D2236] 심의2310~2503 / 서울시 협상완료 및 실시협약체결(2607) | E20: DA건축 | F20: 한화건설 | G20: ALL | H20: 박상원 | L20: 기획 | M20: 5 | N20: 1월심의접수
A21: 20 | B21: D2301 | C21: 덕소5구역 도시환경정비사업 건축외관디자인 | D21: [D2301] 대기 / 준공미정 | E21: 현대엔지니어링 | F21: 현대엔지니어링 | G21: GM | H21: 박상원 | J21: 6개동, 990세대 | L21: 대기 | N21: GM
A22: 21 | B22: D2302 | C22: 부산 범천4재개발정비사업 건축외관디자인 | D22: [D2302] 심의2302~07 / 대기 / 준공미정 | E22: 영탑건축사사무소 | F22: 현대건설 | G22: P3 | H22: 김주경 | J22: 18개동 | L22: 대기 | N22: T2
A23: 22 | B23: D2303 | C23: 방화동연계형 1BL 익스테리어 디자인 | D23: [D2303] 심의2304~07, 2409~2411 / 준공미정 | E23: 한화건설 | F23: 한화건설 | G23: P3 | H23: 김주경 | J23: 4개동 | L23: 대기
A24: 23 | B24: D2306,7 | C24: 울산 신정동 주상복합 건축외관디자인, 상환경디자인 | D24: [D2306,7]심의2304~2312 / 분양2312~2402 / 기본2409~2507 / 설계2411~2507 / 실시 2509~2601 / 준공2702 | E24: 비케이파트너스 | F24: 현대엔지니어링 | G24: P1 | H24: 박제정 | I24: 홍대성 | J24: 4개동/상환경 | K24: 1차 작업중 | L24: 현장지원 | M24: 2 | N24: 특화+상환경
A25: 24 | B25: D2308 | C25: 수서역 환승센터 복합개발사업 외부특화분야, 색채, 사인분야 | D25: [D2308] 심의2303~04, 2306~08, 2408/ 2508 실시계획인가승인 | E25: 혜원까치건축 | F25: 한화건설 | G25: ALL | H25: 박상원 | J25: 9개동 복합시설 | L25: 기본 | M25: 4 | N25: GM,T1,T2
A26: 25 | B26: D2310 | C26: 천안 구성 1,2구역재개발 익스테리어디자인 | D26: [D2310] 심의2307~2409, 2503, 2609~ / 대기 / 준공미정 | E26: 한화건설 | F26: 한화건설 | G26: P2 | H26: 최은진 | J26: 10개동 | L26: 기획 | M26: 5
A27: 26 | B27: D2314 | C27: 남양주시 화도읍 묵현리 아파트 외관특화디자인 | D27: [D2314] 심의2307~11 / 대기 / 준공미정 | E27: 와이티월드 | F27: 두산건설 | G27: P1 | H27: 박제정 | J27: 8개동 | L27: 대기
A28: 27 | B28: D2315 | C28: 청주 강서2지구 지역주택조합 환경색채/공용홀 디자인 | D28: [D2315] 심의2308~12 / 분양2501~ / 준공2705 | E28: 롯데건설 | F28: 롯데건설 | G28: P3 | H28: 김주경 | J28: 10개동 | L28: 현장지원 | M28: 2 | N28: 외주-1
A29: 28 | B29: D2316 | C29: 인천시 계양구 효성동 101-21,123-30번지 공동주택 환경색채 및 공용홀디자인 | D29: [D2316] 심의2309~12/분양2312~2403/기본2405~06/설계2406~/색채2406~/준공2707(3블럭),2711(4블럭) | E29: 롯데건설 | F29: 롯데건설 | G29: P2 | H29: 최은진 | J29: 30개동 | K29: 최종납품 완료(24.09.25) | L29: 현장지원 | M29: 2
A30: 29 | B30: D2321 | C30: 여수 소호동 공동주택 익스테리어 디자인 | D30: [D2321] 심의2402~04 / 대기 / 준공미정 | E30: 애이엔유건축 | F30: 한화건설 | G30: P1 | H30: 박제정 | J30: 1개동,오피스텔 | L30: 대기
A31: 30 | B31: D2324 | C31: 부산 괴정6구역 재개발정비사업 환경색채/공용홀 디자인설계용역 | D31: [D2324] 심의2312~2403 / 대기 / 준공2908 | E31: 롯데건설 | F31: 롯데건설 | G31: P3 | H31: 김주경 | J31: 9개동 | L31: 대기
A32: 31 | B32: D2326 | C32: 인천 청라 C18BL 오피스텔 환경색채 디자인 | D32: [D2326] 심의2401~01 / 기본2406~08 / 설계2409~11 / 준공미정 | E32: 대우건설 | F32: 대우건설 | G32: P2 | H32: 최은진 | I32: 외주 | J32: 2개동 | K32: 2차 작업중 | L32: 현장지원 | M32: 2
A33: 32 | B33: D2327 | C33: 부산동래사적공원 외관특화디자인 | D33: [D2327] 심의2312~2403 / 분양2404~2405 / 기본2610~ / 준공미정 | E33: 대광건영 | F33: 대광건영 | G33: P2 | H33: 최은진 | L33: 기본 | M33: 4
A34: 33 | B34: D2328 | C34: 서인제권 12사단, 지작사 관사 색채디자인 | D34: [D2328] 색채2401 / 대기 | E34: 희림건축 | F34: - | G34: GM | H34: 박상원 | L34: 대기 | N34: GM
A35: 34 | B35: D2405 | C35: 인천검단 AA24BL 중흥S-클래스 색채 및 환경디자인 | D35: [D2405] 심의2403~ / 기본2512~2602, 2610~ / 준공미정 | E35: 중흥건설 | F35: 중흥건설 | G35: P2 | H35: 최은진 | J35: 12개동 | L35: 기본 | M35: 4
A36: 35 | B36: D2406 | C36: 신림2재정비촉진구역 주택재개발정비사업 환경색채/공용홀/사인디자인 | D36: [D2406] 심의2404~10, 2501, 2503, 2508~10 / 분양2601~ / 준공미정 | E36: 롯데(50)대우(50) | F36: 롯데건설/대우건설 | G36: P1 | H36: 박제정 | J36: 20개동 컨소 | L36: 기획 | M36: 5
A37: 36 | B37: D2411 | C37: 상인천초교주변 재개발 익스테리어디자인용역 | D37: [D2320] 심의2407~08, 2411~2503, 2506~09 / 분양2510~11 / 기본 2512~2605, 2607~10/ 준공미정 | E37: 한화건설 | F37: 한화건설 | G37: P1 | H37: 박제정 | J37: 24개동 컨소 | L37: 기본 | M37: 4 | N37: T2
A38: 37 | B38: D2415 | C38: 청주 사모2구역 재개발 정비사업 | D38: [D2415] 심의2407~10, 2501~02, 2512~2606 / 분양2606~09, 2610~ / 준공미정 | E38: 현대 대우 두산 한신 | F38: 현대 대우 두산 한신 | G38: P1 | H38: 박제정 | J38: 31개동 컨소 | L38: 기획 | M38: 5
A39: 38 | B39: D2416(1) | C39: 고양창릉 S-2, S-8BL 토탈디자인 | D39: [D2416] 심의2410~12 / 기본2504~2507 / 실시2509~2603 / 준공미정 | E39: 토문건축 | F39: LH | G39: P2 | H39: 최은진 | J39: 36개동 | L39: 현장지원 | M39: 2
A40: 39 | B40: D2420 | C40: 과천8,9단지 재건축정비사업 외관디자인 | D40: [D2420] 심의2506~ | E40: 현대건설 | F40: 현대건설 | G40: P2 | H40: 최은진 | J40: 27개동 | L40: 기획 | M40: 5 | N40: 디에이치 르블리스
...

Sheet 팀별_점수합계
A1: 팀 | B1: 점수(대기 제외) | C1: 프로젝트 수 | D1: 대기 건수 | E1: 복수팀/ALL 건수
A2: P1 | B2: =SUMIFS(Design_PROJECT!$M:$M,Design_PROJECT!$G:$G,"*"&A2&"*",Design_PROJECT!$L:$L,"<>대기")+SUMIFS(Design_PROJECT!$M:$M,Design_PROJECT!$G:$G,"ALL",Design_PROJECT!$L:$L,"<>대기") | C2: =COUNTIF(Design_PROJECT!$G:$G,"*"&A2&"*")+COUNTIF(Design_PROJECT!$G:$G,"ALL") | D2: =COUNTIFS(Design_PROJECT!$G:$G,"*"&A2&"*",Design_PROJECT!$L:$L,"대기")+COUNTIFS(Design_PROJECT!$G:$G,"ALL",Design_PROJECT!$L:$L,"대기") | E2: =COUNTIF(Design_PROJECT!$G:$G,"*"&A2&",*")+COUNTIF(Design_PROJECT!$G:$G,"*,"&A2&"*")+COUNTIF(Design_PROJECT!$G:$G,"ALL")
A3: P2 | B3: =SUMIFS(Design_PROJECT!$M:$M,Design_PROJECT!$G:$G,"*"&A3&"*",Design_PROJECT!$L:$L,"<>대기")+SUMIFS(Design_PROJECT!$M:$M,Design_PROJECT!$G:$G,"ALL",Design_PROJECT!$L:$L,"<>대기") | C3: =COUNTIF(Design_PROJECT!$G:$G,"*"&A3&"*")+COUNTIF(Design_PROJECT!$G:$G,"ALL") | D3: =COUNTIFS(Design_PROJECT!$G:$G,"*"&A3&"*",Design_PROJECT!$L:$L,"대기")+COUNTIFS(Design_PROJECT!$G:$G,"ALL",Design_PROJECT!$L:$L,"대기") | E3: =COUNTIF(Design_PROJECT!$G:$G,"*"&A3&",*")+COUNTIF(Design_PROJECT!$G:$G,"*,"&A3&"*")+COUNTIF(Design_PROJECT!$G:$G,"ALL")
A4: P3 | B4: =SUMIFS(Design_PROJECT!$M:$M,Design_PROJECT!$G:$G,"*"&A4&"*",Design_PROJECT!$L:$L,"<>대기")+SUMIFS(Design_PROJECT!$M:$M,Design_PROJECT!$G:$G,"ALL",Design_PROJECT!$L:$L,"<>대기") | C4: =COUNTIF(Design_PROJECT!$G:$G,"*"&A4&"*")+COUNTIF(Design_PROJECT!$G:$G,"ALL") | D4: =COUNTIFS(Design_PROJECT!$G:$G,"*"&A4&"*",Design_PROJECT!$L:$L,"대기")+COUNTIFS(Design_PROJECT!$G:$G,"ALL",Design_PROJECT!$L:$L,"대기") | E4: =COUNTIF(Design_PROJECT!$G:$G,"*"&A4&",*")+COUNTIF(Design_PROJECT!$G:$G,"*,"&A4&"*")+COUNTIF(Design_PROJECT!$G:$G,"ALL")
A5: GM | B5: =SUMIFS(Design_PROJECT!$M:$M,Design_PROJECT!$G:$G,"*"&A5&"*",Design_PROJECT!$L:$L,"<>대기")+SUMIFS(Design_PROJECT!$M:$M,Design_PROJECT!$G:$G,"ALL",Design_PROJECT!$L:$L,"<>대기") | C5: =COUNTIF(Design_PROJECT!$G:$G,"*"&A5&"*")+COUNTIF(Design_PROJECT!$G:$G,"ALL") | D5: =COUNTIFS(Design_PROJECT!$G:$G,"*"&A5&"*",Design_PROJECT!$L:$L,"대기")+COUNTIFS(Design_PROJECT!$G:$G,"ALL",Design_PROJECT!$L:$L,"대기") | E5: =COUNTIF(Design_PROJECT!$G:$G,"*"&A5&",*")+COUNTIF(Design_PROJECT!$G:$G,"*,"&A5&"*")+COUNTIF(Design_PROJECT!$G:$G,"ALL")
A6: TEAM | B6: =SUMIFS(Design_PROJECT!$M:$M,Design_PROJECT!$G:$G,"*"&A6&"*",Design_PROJECT!$L:$L,"<>대기")+SUMIFS(Design_PROJECT!$M:$M,Design_PROJECT!$G:$G,"ALL",Design_PROJECT!$L:$L,"<>대기") | C6: =COUNTIF(Design_PROJECT!$G:$G,"*"&A6&"*")+COUNTIF(Design_PROJECT!$G:$G,"ALL") | D6: =COUNTIFS(Design_PROJECT!$G:$G,"*"&A6&"*",Design_PROJECT!$L:$L,"대기")+COUNTIFS(Design_PROJECT!$G:$G,"ALL",Design_PROJECT!$L:$L,"대기") | E6: =COUNTIF(Design_PROJECT!$G:$G,"*"&A6&",*")+COUNTIF(Design_PROJECT!$G:$G,"*,"&A6&"*")+COUNTIF(Design_PROJECT!$G:$G,"ALL")
A7: 합계(복수팀 포함) | B7: =SUM(B2:B6) | C7: =SUM(C2:C6) | D7: =SUM(D2:D6)
A8: 원본 합계 | B8: =SUMIFS(Design_PROJECT!$M:$M,Design_PROJECT!$L:$L,"<>대기") | C8: =COUNTA(Design_PROJECT!$G:$G)-1 | D8: =COUNTIF(Design_PROJECT!$L:$L,"대기")
A10: ※ 점수는 현재단계가 '대기'인 프로젝트를 제외한 합계. 소속팀이 복수(예: GM,P2) 또는 ALL인 프로젝트는 해당 팀 모두에 집계

Sheet 팀별_업무분석
A1: 소속팀 | B1: 기획 | C1: 기본 | D1: 실시 | E1: 대기 | F1: 현장지원 | G1: 현장지원 제외 건수
A2: P1 | B2: =IFERROR((COUNTIFS(Design_PROJECT!$G:$G,"*"&$A2&"*",Design_PROJECT!$L:$L,B$1)+COUNTIFS(Design_PROJECT!$G:$G,"ALL",Design_PROJECT!$L:$L,B$1))/$G2,0) | C2: =IFERROR((COUNTIFS(Design_PROJECT!$G:$G,"*"&$A2&"*",Design_PROJECT!$L:$L,C$1)+COUNTIFS(Design_PROJECT!$G:$G,"ALL",Design_PROJECT!$L:$L,C$1))/$G2,0) | D2: =IFERROR((COUNTIFS(Design_PROJECT!$G:$G,"*"&$A2&"*",Design_PROJECT!$L:$L,D$1)+COUNTIFS(Design_PROJECT!$G:$G,"ALL",Design_PROJECT!$L:$L,D$1))/$G2,0) | E2: =IFERROR((COUNTIFS(Design_PROJECT!$G:$G,"*"&$A2&"*",Design_PROJECT!$L:$L,E$1)+COUNTIFS(Design_PROJECT!$G:$G,"ALL",Design_PROJECT!$L:$L,E$1))/$G2,0) | F2: =COUNTIFS(Design_PROJECT!$G:$G,"*"&$A2&"*",Design_PROJECT!$L:$L,F$1)+COUNTIFS(Design_PROJECT!$G:$G,"ALL",Design_PROJECT!$L:$L,F$1) | G2: =COUNTIFS(Design_PROJECT!$G:$G,"*"&$A2&"*",Design_PROJECT!$L:$L,"<>현장지원")+COUNTIFS(Design_PROJECT!$G:$G,"ALL",Design_PROJECT!$L:$L,"<>현장지원")
A3: P2 | B3: =IFERROR((COUNTIFS(Design_PROJECT!$G:$G,"*"&$A3&"*",Design_PROJECT!$L:$L,B$1)+COUNTIFS(Design_PROJECT!$G:$G,"ALL",Design_PROJECT!$L:$L,B$1))/$G3,0) | C3: =IFERROR((COUNTIFS(Design_PROJECT!$G:$G,"*"&$A3&"*",Design_PROJECT!$L:$L,C$1)+COUNTIFS(Design_PROJECT!$G:$G,"ALL",Design_PROJECT!$L:$L,C$1))/$G3,0) | D3: =IFERROR((COUNTIFS(Design_PROJECT!$G:$G,"*"&$A3&"*",Design_PROJECT!$L:$L,D$1)+COUNTIFS(Design_PROJECT!$G:$G,"ALL",Design_PROJECT!$L:$L,D$1))/$G3,0) | E3: =IFERROR((COUNTIFS(Design_PROJECT!$G:$G,"*"&$A3&"*",Design_PROJECT!$L:$L,E$1)+COUNTIFS(Design_PROJECT!$G:$G,"ALL",Design_PROJECT!$L:$L,E$1))/$G3,0) | F3: =COUNTIFS(Design_PROJECT!$G:$G,"*"&$A3&"*",Design_PROJECT!$L:$L,F$1)+COUNTIFS(Design_PROJECT!$G:$G,"ALL",Design_PROJECT!$L:$L,F$1) | G3: =COUNTIFS(Design_PROJECT!$G:$G,"*"&$A3&"*",Design_PROJECT!$L:$L,"<>현장지원")+COUNTIFS(Design_PROJECT!$G:$G,"ALL",Design_PROJECT!$L:$L,"<>현장지원")
A4: P3 | B4: =IFERROR((COUNTIFS(Design_PROJECT!$G:$G,"*"&$A4&"*",Design_PROJECT!$L:$L,B$1)+COUNTIFS(Design_PROJECT!$G:$G,"ALL",Design_PROJECT!$L:$L,B$1))/$G4,0) | C4: =IFERROR((COUNTIFS(Design_PROJECT!$G:$G,"*"&$A4&"*",Design_PROJECT!$L:$L,C$1)+COUNTIFS(Design_PROJECT!$G:$G,"ALL",Design_PROJECT!$L:$L,C$1))/$G4,0) | D4: =IFERROR((COUNTIFS(Design_PROJECT!$G:$G,"*"&$A4&"*",Design_PROJECT!$L:$L,D$1)+COUNTIFS(Design_PROJECT!$G:$G,"ALL",Design_PROJECT!$L:$L,D$1))/$G4,0) | E4: =IFERROR((COUNTIFS(Design_PROJECT!$G:$G,"*"&$A4&"*",Design_PROJECT!$L:$L,E$1)+COUNTIFS(Design_PROJECT!$G:$G,"ALL",Design_PROJECT!$L:$L,E$1))/$G4,0) | F4: =COUNTIFS(Design_PROJECT!$G:$G,"*"&$A4&"*",Design_PROJECT!$L:$L,F$1)+COUNTIFS(Design_PROJECT!$G:$G,"ALL",Design_PROJECT!$L:$L,F$1) | G4: =COUNTIFS(Design_PROJECT!$G:$G,"*"&$A4&"*",Design_PROJECT!$L:$L,"<>현장지원")+COUNTIFS(Design_PROJECT!$G:$G,"ALL",Design_PROJECT!$L:$L,"<>현장지원")
A5: GM | B5: =IFERROR((COUNTIFS(Design_PROJECT!$G:$G,"*"&$A5&"*",Design_PROJECT!$L:$L,B$1)+COUNTIFS(Design_PROJECT!$G:$G,"ALL",Design_PROJECT!$L:$L,B$1))/$G5,0) | C5: =IFERROR((COUNTIFS(Design_PROJECT!$G:$G,"*"&$A5&"*",Design_PROJECT!$L:$L,C$1)+COUNTIFS(Design_PROJECT!$G:$G,"ALL",Design_PROJECT!$L:$L,C$1))/$G5,0) | D5: =IFERROR((COUNTIFS(Design_PROJECT!$G:$G,"*"&$A5&"*",Design_PROJECT!$L:$L,D$1)+COUNTIFS(Design_PROJECT!$G:$G,"ALL",Design_PROJECT!$L:$L,D$1))/$G5,0) | E5: =IFERROR((COUNTIFS(Design_PROJECT!$G:$G,"*"&$A5&"*",Design_PROJECT!$L:$L,E$1)+COUNTIFS(Design_PROJECT!$G:$G,"ALL",Design_PROJECT!$L:$L,E$1))/$G5,0) | F5: =COUNTIFS(Design_PROJECT!$G:$G,"*"&$A5&"*",Design_PROJECT!$L:$L,F$1)+COUNTIFS(Design_PROJECT!$G:$G,"ALL",Design_PROJECT!$L:$L,F$1) | G5: =COUNTIFS(Design_PROJECT!$G:$G,"*"&$A5&"*",Design_PROJECT!$L:$L,"<>현장지원")+COUNTIFS(Design_PROJECT!$G:$G,"ALL",Design_PROJECT!$L:$L,"<>현장지원")
A6: TEAM | B6: =IFERROR((COUNTIFS(Design_PROJECT!$G:$G,"*"&$A6&"*",Design_PROJECT!$L:$L,B$1)+COUNTIFS(Design_PROJECT!$G:$G,"ALL",Design_PROJECT!$L:$L,B$1))/$G6,0) | C6: =IFERROR((COUNTIFS(Design_PROJECT!$G:$G,"*"&$A6&"*",Design_PROJECT!$L:$L,C$1)+COUNTIFS(Design_PROJECT!$G:$G,"ALL",Design_PROJECT!$L:$L,C$1))/$G6,0) | D6: =IFERROR((COUNTIFS(Design_PROJECT!$G:$G,"*"&$A6&"*",Design_PROJECT!$L:$L,D$1)+COUNTIFS(Design_PROJECT!$G:$G,"ALL",Design_PROJECT!$L:$L,D$1))/$G6,0) | E6: =IFERROR((COUNTIFS(Design_PROJECT!$G:$G,"*"&$A6&"*",Design_PROJECT!$L:$L,E$1)+COUNTIFS(Design_PROJECT!$G:$G,"ALL",Design_PROJECT!$L:$L,E$1))/$G6,0) | F6: =COUNTIFS(Design_PROJECT!$G:$G,"*"&$A6&"*",Design_PROJECT!$L:$L,F$1)+COUNTIFS(Design_PROJECT!$G:$G,"ALL",Design_PROJECT!$L:$L,F$1) | G6: =COUNTIFS(Design_PROJECT!$G:$G,"*"&$A6&"*",Design_PROJECT!$L:$L,"<>현장지원")+COUNTIFS(Design_PROJECT!$G:$G,"ALL",Design_PROJECT!$L:$L,"<>현장지원")
A8: ※ 비율 = 해당 단계 건수 / (현장지원 제외 프로젝트 수). 현장지원은 건수. 소속팀 ALL은 전 팀에 포함
